Всем привет, никто часом не сталкивался с ситуёвиной: 
TASK [Creates VM from temp 'ALCE-173-CLI'] **************************************************************************
An exception occurred during task execution. To see the full traceback, use -vvv. The error was: AttributeError: module 'inspect' has no attribute 'getargspec'
fatal: [localhost]: FAILED! => {"changed": false, "msg": "module 'inspect' has no attribute 'getargspec'"}

Создание vm на oVirt 4.5 с помощью Ansible из шаблона
Сontrol node:
❯ python3 -m pip -V
pip 22.2.2 from /usr/lib/python3.11/site-packages/pip (python 3.11)
❯ ansible --version
ansible [core 2.14.1]
Manage node:
❯ python3 -v 
python 3.9.6


❯ ls -l python3
lrwxrwxrwx. 1 root root 10 Jan 12 15:11 python3 -> python3.11
❯ 
❯ rm python3
rm: cannot remove 'python3': Permission denied
❯ 
❯ sudo rm python3
❯ ls -l python3
ls: cannot access 'python3': No such file or directory
❯  ln -s /usr/bin/python3.9 /usr/bin/python3
ln: failed to create symbolic link '/usr/bin/python3': Permission denied
❯ sudo ln -s /usr/bin/python3.9 /usr/bin/python3
❯ ls -l python3
lrwxrwxrwx. 1 root root 18 Jan 25 16:49 python3 -> /usr/bin/python3.9
❯ python3 --version
Python 3.9.16


